<?xml version="1.0" ?>
<robot xmlns:xacro="http://ros.org/wiki/xacro">
<xacro:macro name="motoman_motomini" params="prefix">

  <!-- Properties -->
  <material name="yaskawa_blue">
      <color rgba="0.12941 0.14902 0.74902 1" />
  </material>
  <material name="white">
    <color rgba="1.0 1.0 1.0 1.0"/>
  </material>
  <material name="grey">
    <color rgba="0.4 0.4 0.4 1.0"/>
  </material>
  <material name="silver">
    <color rgba="0.6 0.6 0.6 1.0"/>
  </material>
  <!-- assumption value for mass TODO: update with correct mass -->
  <xacro:property name="mass0" value="3.0"/>
  <xacro:property name="mass1" value="1.8"/>
  <xacro:property name="mass2" value="1.2"/>
  <xacro:property name="mass3" value="0.4"/>
  <xacro:property name="mass4" value="0.34"/>
  <xacro:property name="mass5" value="0.246"/>
  <xacro:property name="mass6" value="0.0245"/>

  <!-- Import all Gazebo-customization elements, including Gazebo colors -->
  <xacro:include filename="$(find motoman_motomini_support)/urdf/motomini.gazebo" />
    <group name="motomini_arm">
        <joint name="base_link" />
        <joint name="link_1_s" />
        <joint name="link_2_l" />
        <joint name="link_3_u" />
        <joint name="link_4_r" />
        <joint name="link_5_b" />
        <joint name="link_6_t" />
    </group>
  <!-- link list -->
  <link name="${prefix}base_link">
    <visual>
      <geometry>
        <mesh filename="package://motoman_motomini_support/meshes/motomini/visual/base_link.stl"/>
      </geometry>
      <material name="silver"/>
    </visual>
    <collision>
      <geometry>
        <mesh filename="package://motoman_motomini_support/meshes/motomini/collision/base_link.stl"/>
      </geometry>
    </collision>
    <inertial>
      <mass value="${mass0}" />
      <inertia ixx="0.03" iyy="0.03" izz="0.03" ixy="0.0" ixz="0.0" iyz="0.0" />
    </inertial>
  </link>
  <link name="${prefix}link_1_s">
    <visual>
      <geometry>
        <mesh filename="package://motoman_motomini_support/meshes/motomini/visual/link_1_s.stl"/>
      </geometry>
      <material name="yaskawa_blue"/>
    </visual>
    <collision>
      <geometry>
        <mesh filename="package://motoman_motomini_support/meshes/motomini/collision/link_1_s.stl"/>
      </geometry>
    </collision>
    <inertial>
      <mass value="${mass1}" />
      <inertia ixx="0.01" iyy="0.01" izz="0.01" ixy="0.0" ixz="0.0" iyz="0.0" />
    </inertial>
  </link>
  <link name="${prefix}link_2_l">
    <visual>
      <geometry>
        <mesh filename="package://motoman_motomini_support/meshes/motomini/visual/link_2_l.stl"/>
      </geometry>
      <material name="yaskawa_blue"/>
    </visual>
    <collision>
      <geometry>
        <mesh filename="package://motoman_motomini_support/meshes/motomini/collision/link_2_l.stl"/>
      </geometry>
    </collision>
    <inertial>
      <mass value="${mass2}" />
      <inertia ixx="0.01" iyy="0.01" izz="0.01" ixy="0.0" ixz="0.0" iyz="0.0" />
    </inertial>
  </link>
  <link name="${prefix}link_3_u">
    <visual>
      <geometry>
        <mesh filename="package://motoman_motomini_support/meshes/motomini/visual/link_3_u.stl"/>
      </geometry>
      <material name="yaskawa_blue"/>
    </visual>
    <collision>
      <geometry>
        <mesh filename="package://motoman_motomini_support/meshes/motomini/collision/link_3_u.stl"/>
      </geometry>
    </collision>
    <inertial>
      <mass value="${mass3}" />
      <inertia ixx="0.001" iyy="0.001" izz="0.001" ixy="0.0" ixz="0.0" iyz="0.0" />
    </inertial>
  </link>
  <link name="${prefix}link_4_r">
    <visual>
      <geometry>
        <mesh filename="package://motoman_motomini_support/meshes/motomini/visual/link_4_r.stl"/>
      </geometry>
      <material name="yaskawa_blue"/>
    </visual>
    <collision>
      <geometry>
        <mesh filename="package://motoman_motomini_support/meshes/motomini/collision/link_4_r.stl"/>
      </geometry>
    </collision>
    <inertial>
      <mass value="${mass4}" />
      <inertia ixx="0.001" iyy="0.001" izz="0.001" ixy="0.0" ixz="0.0" iyz="0.0" />
    </inertial>
  </link>
  <link name="${prefix}link_5_b">
    <visual>
      <geometry>
        <mesh filename="package://motoman_motomini_support/meshes/motomini/visual/link_5_b.stl"/>
      </geometry>
      <material name="yaskawa_blue"/>
    </visual>
    <collision>
      <geometry>
        <mesh filename="package://motoman_motomini_support/meshes/motomini/collision/link_5_b.stl"/>
      </geometry>
    </collision>
    <inertial>
      <mass value="${mass5}" />
      <inertia ixx="0.0003" iyy="0.0003" izz="0.0003" ixy="0.0" ixz="0.0" iyz="0.0" />
    </inertial>
  </link>
  <link name="${prefix}link_6_t">
    <visual>
      <geometry>
        <mesh filename="package://motoman_motomini_support/meshes/motomini/visual/link_6_t.stl"/>
      </geometry>
      <material name="grey"/>
    </visual>
    <collision>
      <geometry>
        <mesh filename="package://motoman_motomini_support/meshes/motomini/collision/link_6_t.stl"/>
      </geometry>
    </collision>
    <inertial>
      <mass value="${mass6}" />
      <inertia ixx="4.5E-06" iyy="4.5E-06" izz="4.5E-06" ixy="0.0" ixz="0.0" iyz="0.0" />
    </inertial>
  </link>
  <link name="${prefix}tool0"/>
  <link name="${prefix}logo_f">
    <visual>
      <geometry>
        <mesh filename="package://motoman_motomini_support/meshes/motomini/visual/logo.stl" scale="1.0 1.0 1.0"/>
      </geometry>
      <material name="white"/>
    </visual>
  </link>
  <link name="${prefix}logo_b">
    <visual>
      <geometry>
        <mesh filename="package://motoman_motomini_support/meshes/motomini/visual/logo.stl" scale="1.0 1.0 1.0"/>
      </geometry>
      <material name="white"/>
    </visual>
  </link>
  <!-- end of link list -->

  <!-- joint list -->
  <joint name="${prefix}joint_1_s" type="revolute">
    <parent link="${prefix}base_link"/>
    <child link="${prefix}link_1_s"/>
    <origin xyz="0 0 0.103" rpy="0 0 0" />
    <axis xyz="0 0 1" />
    <limit lower="-2.9670" upper="2.9670" effort="0.12" velocity="5.4977"/>
    <dynamics damping="0.7"/>
  </joint>
  <joint name="${prefix}joint_2_l" type="revolute">
    <parent link="${prefix}link_1_s"/>
    <child link="${prefix}link_2_l"/>
    <origin xyz="0.020 0 0" rpy="0 0 0" />
    <axis xyz="0 1 0" />
    <limit lower="-1.4835" upper="1.5707" effort="0.12" velocity="5.4977"/>
    <dynamics damping="0.7"/>
  </joint>
  <joint name="${prefix}joint_3_u" type="revolute">
    <parent link="${prefix}link_2_l"/>
    <child link="${prefix}link_3_u"/>
    <origin xyz="0 0 0.165" rpy="0 0 0" />
    <axis xyz="0 -1 0" />
    <limit lower="-0.8726" upper="1.5707" effort="0.12" velocity="7.3304"/>
    <dynamics damping="0.7"/>
  </joint>
  <joint name="${prefix}joint_4_r" type="revolute">
    <parent link="${prefix}link_3_u"/>
    <child link="${prefix}link_4_r"/>
    <origin xyz="0.165 0 0" rpy="0 0 0" />
    <axis xyz="-1 0 0" />
    <limit lower="-2.4434" upper="2.4434" effort="0.07" velocity="10.4719"/>
    <dynamics damping="0.7"/>
  </joint>
  <joint name="${prefix}joint_5_b" type="revolute">
    <parent link="${prefix}link_4_r"/>
    <child link="${prefix}link_5_b"/>
    <origin xyz="0 0 0" rpy="0 0 0" />
    <axis xyz="0 -1 0" />
    <limit lower="-0.5235" upper="3.6651" effort="0.07" velocity="10.4719"/>
    <dynamics damping="0.7"/>
  </joint>
  <joint name="${prefix}joint_6_t" type="revolute">
    <parent link="${prefix}link_5_b"/>
    <child link="${prefix}link_6_t"/>
    <origin xyz="0 0 0" rpy="0 0 0" />
    <axis xyz="0 0 1" />
    <limit lower="-6.2831" upper="6.2831" effort="0.07" velocity="10.4719"/>
    <dynamics damping="0.7"/>
  </joint>
  <joint name="${prefix}joint_6_t-tool0" type="fixed">
    <origin xyz="0 0 -0.040 " rpy="${pi} 0 0"/>
    <parent link="${prefix}link_6_t"/>
    <child link="${prefix}tool0"/>
  </joint>
  <!-- end of joint list -->

  <!-- ROS base_link to Robot Manufacturer World Coordinates transform -->
  <link name="${prefix}base" />
  <joint name="${prefix}base_link-base" type="fixed">
    <origin xyz="0 0 0.103" rpy="0 0 0"/>
    <parent link="${prefix}base_link"/>
    <child link="${prefix}base"/>
  </joint>
  <!-- Attach addition logo on link_4_r -->
  <joint name="${prefix}joint_4_r-logo_f" type="fixed">
    <parent link="${prefix}link_4_r"/>
    <child link="${prefix}logo_f"/>
    <origin xyz="0.02 0.04 -0.01" rpy="0 0 0"/>
    <axis xyz="0 0 1"/>
  </joint>
  <joint name="${prefix}joint_4_r-logo_b" type="fixed">
    <parent link="${prefix}link_4_r"/>
    <child link="${prefix}logo_b"/>
    <origin xyz="-0.10 -0.04 -0.01" rpy="0 0 ${pi}"/>
    <axis xyz="0 0 1"/>
  </joint>

  <!--  Transmission Setup for Gazebo Control TODO: Update with correct info -->
  <transmission name="tran1">
    <type>transmission_interface/SimpleTransmission</type>
    <joint name="${prefix}joint_1_s">
      <hardwareInterface>hardware_interface/PositionJointInterface</hardwareInterface>
    </joint>
    <actuator name="motor_1">
      <hardwareInterface>hardware_interface/PositionJointInterface</hardwareInterface>
      <mechanicalReduction>33</mechanicalReduction>
    </actuator>
  </transmission>

  <transmission name="tran2">
    <type>transmission_interface/SimpleTransmission</type>
    <joint name="${prefix}joint_2_l">
      <hardwareInterface>hardware_interface/PositionJointInterface</hardwareInterface>
    </joint>
    <actuator name="motor_2">
      <hardwareInterface>hardware_interface/PositionJointInterface</hardwareInterface>
      <mechanicalReduction>33</mechanicalReduction>
    </actuator>
  </transmission>

  <transmission name="tran3">
    <type>transmission_interface/SimpleTransmission</type>
    <joint name="${prefix}joint_3_u">
      <hardwareInterface>hardware_interface/PositionJointInterface</hardwareInterface>
    </joint>
    <actuator name="motor_3">
      <hardwareInterface>hardware_interface/PositionJointInterface</hardwareInterface>
      <mechanicalReduction>33</mechanicalReduction>
    </actuator>
  </transmission>

  <transmission name="tran4">
    <type>transmission_interface/SimpleTransmission</type>
    <joint name="${prefix}joint_4_r">
      <hardwareInterface>hardware_interface/PositionJointInterface</hardwareInterface>
    </joint>
    <actuator name="motor_4">
      <hardwareInterface>hardware_interface/PositionJointInterface</hardwareInterface>
      <mechanicalReduction>25</mechanicalReduction>
    </actuator>
  </transmission>

  <transmission name="tran5">
    <type>transmission_interface/SimpleTransmission</type>
    <joint name="${prefix}joint_5_b">
      <hardwareInterface>hardware_interface/PositionJointInterface</hardwareInterface>
    </joint>
    <actuator name="motor_5">
      <hardwareInterface>hardware_interface/PositionJointInterface</hardwareInterface>
      <mechanicalReduction>20</mechanicalReduction>
    </actuator>
  </transmission>

  <transmission name="tran6">
    <type>transmission_interface/SimpleTransmission</type>
    <joint name="${prefix}joint_6_t">
      <hardwareInterface>hardware_interface/PositionJointInterface</hardwareInterface>
    </joint>
    <actuator name="motor_6">
      <hardwareInterface>hardware_interface/PositionJointInterface</hardwareInterface>
      <mechanicalReduction>10</mechanicalReduction>
    </actuator>
  </transmission>

  </xacro:macro>
</robot>


